<!DOCTYPE html>
<html lang="en">
<head>
    <meta charset="UTF-8">
    <meta name="viewport" content="width=device-width, initial-scale=1.0">
    <title>Promise-封装 | 11 - catch 方法与异常穿透</title>
    <script src="./promise.js"></script>
</head>
<body>
    <script>
        //实例化对象
        // let p = new Promise((resolve, reject) => {
        //     setTimeout(() => {
        //         reject('Error');
        //         // resolve('OK');
        //         // throw 'Error';
        //     }, 1000);
        // });

        // //值传递
        // p.then(() => {}, () => {
        //   console.log('value...........', 111);
        // })
        // .then(value=>{
        //     console.log('value1...........', value);
        //     // throw 'Error';
        // }).then(value => {
        //     console.log(333);
        // }).catch(reason => {
        //     console.warn('reason1.........', reason);
        // });

        let p = new Promise((resolve, reject) => {
            setTimeout(() => {
                // resolve('OK');
                // reject('Err');
                // throw '失败啦!';
                console.log('ok................');
            }, 1000);
        });

        p.then(value => {
            console.log('value...........', value);
            throw '失败啦!';
        }).then(value => {
            console.log(222);
        }).then(value => {
            console.log(333);
        }).catch(reason => {
            console.warn('reason.............', reason);
        });


    </script>
</body>
</html>